2024-09-07 19:39:22 DEBUG:busco.run_BUSCO	Command line: /home/lazo_ozal/miniforge3/envs/busco/bin/busco -list-datasets
2024-09-07 19:39:22 INFO:busco.run_BUSCO	***** Start a BUSCO v5.4.3 analysis, current time: 09/07/2024 19:39:22 *****
2024-09-07 19:39:22 DEBUG:busco.ConfigManager	Getting config file
2024-09-07 19:39:22 INFO:busco.ConfigManager	Configuring BUSCO with local environment
2024-09-07 19:39:22 ERROR:busco.BuscoRunner	The parameter "in (--in)" was not provided. Please add it in the config file or provide it through the command line
2024-09-07 19:39:22 DEBUG:busco.BuscoRunner	The parameter "in (--in)" was not provided. Please add it in the config file or provide it through the command line
Traceback (most recent call last):
  File "/home/lazo_ozal/miniforge3/envs/busco/lib/python3.8/configparser.py", line 789, in get
    value = d[option]
  File "/home/lazo_ozal/miniforge3/envs/busco/lib/python3.8/collections/__init__.py", line 898, in __getitem__
    return self.__missing__(key)            # support subclasses that define __missing__
  File "/home/lazo_ozal/miniforge3/envs/busco/lib/python3.8/collections/__init__.py", line 890, in __missing__
    raise KeyError(key)
KeyError: 'in'

During handling of the above exception, another exception occurred:

Traceback (most recent call last):
  File "/home/lazo_ozal/miniforge3/envs/busco/lib/python3.8/site-packages/busco/BuscoConfig.py", line 615, in _check_mandatory_keys_exist
    value = self.get("busco_run", param)
  File "/home/lazo_ozal/miniforge3/envs/busco/lib/python3.8/configparser.py", line 792, in get
    raise NoOptionError(option, section)
configparser.NoOptionError: No option 'in' in section: 'busco_run'

During handling of the above exception, another exception occurred:

Traceback (most recent call last):
  File "/home/lazo_ozal/miniforge3/envs/busco/lib/python3.8/site-packages/busco/run_BUSCO.py", line 70, in run
    self.load_config()
  File "/home/lazo_ozal/miniforge3/envs/busco/lib/python3.8/site-packages/busco/run_BUSCO.py", line 62, in load_config
    self.config_manager.load_busco_config_main()
  File "/home/lazo_ozal/miniforge3/envs/busco/lib/python3.8/site-packages/busco/BuscoLogger.py", line 62, in wrapped_func
    self.retval = func(*args, **kwargs)
  File "/home/lazo_ozal/miniforge3/envs/busco/lib/python3.8/site-packages/busco/ConfigManager.py", line 58, in load_busco_config_main
    self.config_main.validate()
  File "/home/lazo_ozal/miniforge3/envs/busco/lib/python3.8/site-packages/busco/BuscoConfig.py", line 524, in validate
    self._check_mandatory_keys_exist()
  File "/home/lazo_ozal/miniforge3/envs/busco/lib/python3.8/site-packages/busco/BuscoLogger.py", line 58, in wrapped_func
    self.retval = func(*args, **kwargs)
  File "/home/lazo_ozal/miniforge3/envs/busco/lib/python3.8/site-packages/busco/BuscoConfig.py", line 674, in _check_mandatory_keys_exist
    raise BatchFatalError(
busco.Exceptions.BatchFatalError: The parameter "in (--in)" was not provided. Please add it in the config file or provide it through the command line
2024-09-07 19:39:22 ERROR:busco.BuscoRunner	BUSCO analysis failed!
2024-09-07 19:39:22 ERROR:busco.BuscoRunner	Check the logs, read the user guide (https://busco.ezlab.org/busco_userguide.html), and check the BUSCO issue board on https://gitlab.com/ezlab/busco/issues

